
2018-04-16 09:28:33,536 INFO: microblog startup [in D:\blog\app\__init__.py:44]
2018-04-16 09:28:46,230 ERROR: Exception on /edit [POST] [in C:\Python27\lib\site-packages\flask\app.py:1560]
Traceback (most recent call last):
  File "C:\Python27\lib\site-packages\flask\app.py", line 1982, in wsgi_app
    response = self.full_dispatch_request()
  File "C:\Python27\lib\site-packages\flask\app.py", line 1614, in full_dispatch_request
    rv = self.handle_user_exception(e)
  File "C:\Python27\lib\site-packages\flask\app.py", line 1517, in handle_user_exception
    reraise(exc_type, exc_value, tb)
  File "C:\Python27\lib\site-packages\flask\app.py", line 1612, in full_dispatch_request
    rv = self.dispatch_request()
  File "C:\Python27\lib\site-packages\flask\app.py", line 1598, in dispatch_request
    return self.view_functions[rule.endpoint](**req.view_args)
  File "C:\Python27\lib\site-packages\flask_login\utils.py", line 261, in decorated_view
    return func(*args, **kwargs)
  File "D:\blog\app\views.py", line 161, in edit
    db.session.commit()
  File "C:\Python27\lib\site-packages\sqlalchemy\orm\scoping.py", line 153, in do
    return getattr(self.registry(), name)(*args, **kwargs)
  File "C:\Python27\lib\site-packages\sqlalchemy\orm\session.py", line 937, in commit
    self.transaction.commit()
  File "C:\Python27\lib\site-packages\sqlalchemy\orm\session.py", line 461, in commit
    self._prepare_impl()
  File "C:\Python27\lib\site-packages\sqlalchemy\orm\session.py", line 441, in _prepare_impl
    self.session.flush()
  File "C:\Python27\lib\site-packages\sqlalchemy\orm\session.py", line 2237, in flush
    self._flush(objects)
  File "C:\Python27\lib\site-packages\sqlalchemy\orm\session.py", line 2363, in _flush
    transaction.rollback(_capture_exception=True)
  File "C:\Python27\lib\site-packages\sqlalchemy\util\langhelpers.py", line 66, in __exit__
    compat.reraise(exc_type, exc_value, exc_tb)
  File "C:\Python27\lib\site-packages\sqlalchemy\orm\session.py", line 2327, in _flush
    flush_context.execute()
  File "C:\Python27\lib\site-packages\sqlalchemy\orm\unitofwork.py", line 391, in execute
    rec.execute(self)
  File "C:\Python27\lib\site-packages\sqlalchemy\orm\unitofwork.py", line 556, in execute
    uow
  File "C:\Python27\lib\site-packages\sqlalchemy\orm\persistence.py", line 177, in save_obj
    mapper, table, update)
  File "C:\Python27\lib\site-packages\sqlalchemy\orm\persistence.py", line 768, in _emit_update_statements
    execute(statement, multiparams)
  File "C:\Python27\lib\site-packages\sqlalchemy\engine\base.py", line 948, in execute
    return meth(self, multiparams, params)
  File "C:\Python27\lib\site-packages\sqlalchemy\sql\elements.py", line 269, in _execute_on_connection
    return connection._execute_clauseelement(self, multiparams, params)
  File "C:\Python27\lib\site-packages\sqlalchemy\engine\base.py", line 1060, in _execute_clauseelement
    compiled_sql, distilled_params
  File "C:\Python27\lib\site-packages\sqlalchemy\engine\base.py", line 1200, in _execute_context
    context)
  File "C:\Python27\lib\site-packages\sqlalchemy\engine\base.py", line 1413, in _handle_dbapi_exception
    exc_info
  File "C:\Python27\lib\site-packages\sqlalchemy\util\compat.py", line 203, in raise_from_cause
    reraise(type(exception), exception, tb=exc_tb, cause=cause)
  File "C:\Python27\lib\site-packages\sqlalchemy\engine\base.py", line 1193, in _execute_context
    context)
  File "C:\Python27\lib\site-packages\sqlalchemy\engine\default.py", line 507, in do_execute
    cursor.execute(statement, parameters)
IntegrityError: (sqlite3.IntegrityError) UNIQUE constraint failed: user.nickname [SQL: u'UPDATE user SET nickname=?, about_me=? WHERE user.id = ?'] [parameters: (u'dup', u'', 2)] (Background on this error at: http://sqlalche.me/e/gkpj)
2018-04-16 09:30:48,456 INFO: microblog startup [in D:\blog\app\__init__.py:44]
2018-04-16 09:30:56,147 ERROR: Exception on /edit [POST] [in C:\Python27\lib\site-packages\flask\app.py:1560]
Traceback (most recent call last):
  File "C:\Python27\lib\site-packages\flask\app.py", line 1982, in wsgi_app
    response = self.full_dispatch_request()
  File "C:\Python27\lib\site-packages\flask\app.py", line 1614, in full_dispatch_request
    rv = self.handle_user_exception(e)
  File "C:\Python27\lib\site-packages\flask\app.py", line 1517, in handle_user_exception
    reraise(exc_type, exc_value, tb)
  File "C:\Python27\lib\site-packages\flask\app.py", line 1612, in full_dispatch_request
    rv = self.dispatch_request()
  File "C:\Python27\lib\site-packages\flask\app.py", line 1598, in dispatch_request
    return self.view_functions[rule.endpoint](**req.view_args)
  File "C:\Python27\lib\site-packages\flask_login\utils.py", line 261, in decorated_view
    return func(*args, **kwargs)
  File "D:\blog\app\views.py", line 161, in edit
    db.session.commit()
  File "C:\Python27\lib\site-packages\sqlalchemy\orm\scoping.py", line 153, in do
    return getattr(self.registry(), name)(*args, **kwargs)
  File "C:\Python27\lib\site-packages\sqlalchemy\orm\session.py", line 937, in commit
    self.transaction.commit()
  File "C:\Python27\lib\site-packages\sqlalchemy\orm\session.py", line 461, in commit
    self._prepare_impl()
  File "C:\Python27\lib\site-packages\sqlalchemy\orm\session.py", line 441, in _prepare_impl
    self.session.flush()
  File "C:\Python27\lib\site-packages\sqlalchemy\orm\session.py", line 2237, in flush
    self._flush(objects)
  File "C:\Python27\lib\site-packages\sqlalchemy\orm\session.py", line 2363, in _flush
    transaction.rollback(_capture_exception=True)
  File "C:\Python27\lib\site-packages\sqlalchemy\util\langhelpers.py", line 66, in __exit__
    compat.reraise(exc_type, exc_value, exc_tb)
  File "C:\Python27\lib\site-packages\sqlalchemy\orm\session.py", line 2327, in _flush
    flush_context.execute()
  File "C:\Python27\lib\site-packages\sqlalchemy\orm\unitofwork.py", line 391, in execute
    rec.execute(self)
  File "C:\Python27\lib\site-packages\sqlalchemy\orm\unitofwork.py", line 556, in execute
    uow
  File "C:\Python27\lib\site-packages\sqlalchemy\orm\persistence.py", line 177, in save_obj
    mapper, table, update)
  File "C:\Python27\lib\site-packages\sqlalchemy\orm\persistence.py", line 768, in _emit_update_statements
    execute(statement, multiparams)
  File "C:\Python27\lib\site-packages\sqlalchemy\engine\base.py", line 948, in execute
    return meth(self, multiparams, params)
  File "C:\Python27\lib\site-packages\sqlalchemy\sql\elements.py", line 269, in _execute_on_connection
    return connection._execute_clauseelement(self, multiparams, params)
  File "C:\Python27\lib\site-packages\sqlalchemy\engine\base.py", line 1060, in _execute_clauseelement
    compiled_sql, distilled_params
  File "C:\Python27\lib\site-packages\sqlalchemy\engine\base.py", line 1200, in _execute_context
    context)
  File "C:\Python27\lib\site-packages\sqlalchemy\engine\base.py", line 1413, in _handle_dbapi_exception
    exc_info
  File "C:\Python27\lib\site-packages\sqlalchemy\util\compat.py", line 203, in raise_from_cause
    reraise(type(exception), exception, tb=exc_tb, cause=cause)
  File "C:\Python27\lib\site-packages\sqlalchemy\engine\base.py", line 1193, in _execute_context
    context)
  File "C:\Python27\lib\site-packages\sqlalchemy\engine\default.py", line 507, in do_execute
    cursor.execute(statement, parameters)
IntegrityError: (sqlite3.IntegrityError) UNIQUE constraint failed: user.nickname [SQL: u'UPDATE user SET nickname=?, about_me=? WHERE user.id = ?'] [parameters: (u'dup', u'', 2)] (Background on this error at: http://sqlalche.me/e/gkpj)
2018-04-16 09:31:49,829 INFO: microblog startup [in D:\blog\app\__init__.py:44]
2018-04-16 09:31:58,571 ERROR: Exception on /edit [POST] [in C:\Python27\lib\site-packages\flask\app.py:1560]
Traceback (most recent call last):
  File "C:\Python27\lib\site-packages\flask\app.py", line 1982, in wsgi_app
    response = self.full_dispatch_request()
  File "C:\Python27\lib\site-packages\flask\app.py", line 1614, in full_dispatch_request
    rv = self.handle_user_exception(e)
  File "C:\Python27\lib\site-packages\flask\app.py", line 1517, in handle_user_exception
    reraise(exc_type, exc_value, tb)
  File "C:\Python27\lib\site-packages\flask\app.py", line 1612, in full_dispatch_request
    rv = self.dispatch_request()
  File "C:\Python27\lib\site-packages\flask\app.py", line 1598, in dispatch_request
    return self.view_functions[rule.endpoint](**req.view_args)
  File "C:\Python27\lib\site-packages\flask_login\utils.py", line 261, in decorated_view
    return func(*args, **kwargs)
  File "D:\blog\app\views.py", line 161, in edit
    db.session.commit()
  File "C:\Python27\lib\site-packages\sqlalchemy\orm\scoping.py", line 153, in do
    return getattr(self.registry(), name)(*args, **kwargs)
  File "C:\Python27\lib\site-packages\sqlalchemy\orm\session.py", line 937, in commit
    self.transaction.commit()
  File "C:\Python27\lib\site-packages\sqlalchemy\orm\session.py", line 461, in commit
    self._prepare_impl()
  File "C:\Python27\lib\site-packages\sqlalchemy\orm\session.py", line 441, in _prepare_impl
    self.session.flush()
  File "C:\Python27\lib\site-packages\sqlalchemy\orm\session.py", line 2237, in flush
    self._flush(objects)
  File "C:\Python27\lib\site-packages\sqlalchemy\orm\session.py", line 2363, in _flush
    transaction.rollback(_capture_exception=True)
  File "C:\Python27\lib\site-packages\sqlalchemy\util\langhelpers.py", line 66, in __exit__
    compat.reraise(exc_type, exc_value, exc_tb)
  File "C:\Python27\lib\site-packages\sqlalchemy\orm\session.py", line 2327, in _flush
    flush_context.execute()
  File "C:\Python27\lib\site-packages\sqlalchemy\orm\unitofwork.py", line 391, in execute
    rec.execute(self)
  File "C:\Python27\lib\site-packages\sqlalchemy\orm\unitofwork.py", line 556, in execute
    uow
  File "C:\Python27\lib\site-packages\sqlalchemy\orm\persistence.py", line 177, in save_obj
    mapper, table, update)
  File "C:\Python27\lib\site-packages\sqlalchemy\orm\persistence.py", line 768, in _emit_update_statements
    execute(statement, multiparams)
  File "C:\Python27\lib\site-packages\sqlalchemy\engine\base.py", line 948, in execute
    return meth(self, multiparams, params)
  File "C:\Python27\lib\site-packages\sqlalchemy\sql\elements.py", line 269, in _execute_on_connection
    return connection._execute_clauseelement(self, multiparams, params)
  File "C:\Python27\lib\site-packages\sqlalchemy\engine\base.py", line 1060, in _execute_clauseelement
    compiled_sql, distilled_params
  File "C:\Python27\lib\site-packages\sqlalchemy\engine\base.py", line 1200, in _execute_context
    context)
  File "C:\Python27\lib\site-packages\sqlalchemy\engine\base.py", line 1413, in _handle_dbapi_exception
    exc_info
  File "C:\Python27\lib\site-packages\sqlalchemy\util\compat.py", line 203, in raise_from_cause
    reraise(type(exception), exception, tb=exc_tb, cause=cause)
  File "C:\Python27\lib\site-packages\sqlalchemy\engine\base.py", line 1193, in _execute_context
    context)
  File "C:\Python27\lib\site-packages\sqlalchemy\engine\default.py", line 507, in do_execute
    cursor.execute(statement, parameters)
IntegrityError: (sqlite3.IntegrityError) UNIQUE constraint failed: user.nickname [SQL: u'UPDATE user SET nickname=?, about_me=? WHERE user.id = ?'] [parameters: (u'dup', u'', 2)] (Background on this error at: http://sqlalche.me/e/gkpj)
2018-04-16 09:51:38,621 INFO: microblog startup [in D:\blog\app\__init__.py:44]
2018-04-16 09:51:50,489 ERROR: Exception on /edit [POST] [in C:\Python27\lib\site-packages\flask\app.py:1560]
Traceback (most recent call last):
  File "C:\Python27\lib\site-packages\flask\app.py", line 1982, in wsgi_app
    response = self.full_dispatch_request()
  File "C:\Python27\lib\site-packages\flask\app.py", line 1614, in full_dispatch_request
    rv = self.handle_user_exception(e)
  File "C:\Python27\lib\site-packages\flask\app.py", line 1517, in handle_user_exception
    reraise(exc_type, exc_value, tb)
  File "C:\Python27\lib\site-packages\flask\app.py", line 1612, in full_dispatch_request
    rv = self.dispatch_request()
  File "C:\Python27\lib\site-packages\flask\app.py", line 1598, in dispatch_request
    return self.view_functions[rule.endpoint](**req.view_args)
  File "C:\Python27\lib\site-packages\flask_login\utils.py", line 261, in decorated_view
    return func(*args, **kwargs)
  File "D:\blog\app\views.py", line 161, in edit
    db.session.commit()
  File "C:\Python27\lib\site-packages\sqlalchemy\orm\scoping.py", line 153, in do
    return getattr(self.registry(), name)(*args, **kwargs)
  File "C:\Python27\lib\site-packages\sqlalchemy\orm\session.py", line 937, in commit
    self.transaction.commit()
  File "C:\Python27\lib\site-packages\sqlalchemy\orm\session.py", line 461, in commit
    self._prepare_impl()
  File "C:\Python27\lib\site-packages\sqlalchemy\orm\session.py", line 441, in _prepare_impl
    self.session.flush()
  File "C:\Python27\lib\site-packages\sqlalchemy\orm\session.py", line 2237, in flush
    self._flush(objects)
  File "C:\Python27\lib\site-packages\sqlalchemy\orm\session.py", line 2363, in _flush
    transaction.rollback(_capture_exception=True)
  File "C:\Python27\lib\site-packages\sqlalchemy\util\langhelpers.py", line 66, in __exit__
    compat.reraise(exc_type, exc_value, exc_tb)
  File "C:\Python27\lib\site-packages\sqlalchemy\orm\session.py", line 2327, in _flush
    flush_context.execute()
  File "C:\Python27\lib\site-packages\sqlalchemy\orm\unitofwork.py", line 391, in execute
    rec.execute(self)
  File "C:\Python27\lib\site-packages\sqlalchemy\orm\unitofwork.py", line 556, in execute
    uow
  File "C:\Python27\lib\site-packages\sqlalchemy\orm\persistence.py", line 177, in save_obj
    mapper, table, update)
  File "C:\Python27\lib\site-packages\sqlalchemy\orm\persistence.py", line 768, in _emit_update_statements
    execute(statement, multiparams)
  File "C:\Python27\lib\site-packages\sqlalchemy\engine\base.py", line 948, in execute
    return meth(self, multiparams, params)
  File "C:\Python27\lib\site-packages\sqlalchemy\sql\elements.py", line 269, in _execute_on_connection
    return connection._execute_clauseelement(self, multiparams, params)
  File "C:\Python27\lib\site-packages\sqlalchemy\engine\base.py", line 1060, in _execute_clauseelement
    compiled_sql, distilled_params
  File "C:\Python27\lib\site-packages\sqlalchemy\engine\base.py", line 1200, in _execute_context
    context)
  File "C:\Python27\lib\site-packages\sqlalchemy\engine\base.py", line 1413, in _handle_dbapi_exception
    exc_info
  File "C:\Python27\lib\site-packages\sqlalchemy\util\compat.py", line 203, in raise_from_cause
    reraise(type(exception), exception, tb=exc_tb, cause=cause)
  File "C:\Python27\lib\site-packages\sqlalchemy\engine\base.py", line 1193, in _execute_context
    context)
  File "C:\Python27\lib\site-packages\sqlalchemy\engine\default.py", line 507, in do_execute
    cursor.execute(statement, parameters)
IntegrityError: (sqlite3.IntegrityError) UNIQUE constraint failed: user.nickname [SQL: u'UPDATE user SET nickname=?, about_me=? WHERE user.id = ?'] [parameters: (u'dup', u'', 2)] (Background on this error at: http://sqlalche.me/e/gkpj)
2018-04-16 09:57:02,664 INFO: microblog startup [in D:\blog\app\__init__.py:44]
2018-04-16 10:13:01,562 ERROR: Exception on /user/john [GET] [in C:\Python27\lib\site-packages\flask\app.py:1560]
Traceback (most recent call last):
  File "C:\Python27\lib\site-packages\flask\app.py", line 1982, in wsgi_app
    response = self.full_dispatch_request()
  File "C:\Python27\lib\site-packages\flask\app.py", line 1614, in full_dispatch_request
    rv = self.handle_user_exception(e)
  File "C:\Python27\lib\site-packages\flask\app.py", line 1517, in handle_user_exception
    reraise(exc_type, exc_value, tb)
  File "C:\Python27\lib\site-packages\flask\app.py", line 1610, in full_dispatch_request
    rv = self.preprocess_request()
  File "C:\Python27\lib\site-packages\flask\app.py", line 1831, in preprocess_request
    rv = func()
  File "D:\blog\app\views.py", line 86, in before_request
    if g.user.is_authenticated:
  File "C:\Python27\lib\site-packages\werkzeug\local.py", line 347, in __getattr__
    return getattr(self._get_current_object(), name)
  File "C:\Python27\lib\site-packages\werkzeug\local.py", line 306, in _get_current_object
    return self.__local()
  File "C:\Python27\lib\site-packages\flask_login\utils.py", line 26, in <lambda>
    current_user = LocalProxy(lambda: _get_user())
  File "C:\Python27\lib\site-packages\flask_login\utils.py", line 335, in _get_user
    current_app.login_manager._load_user()
  File "C:\Python27\lib\site-packages\flask_login\login_manager.py", line 359, in _load_user
    return self.reload_user()
  File "C:\Python27\lib\site-packages\flask_login\login_manager.py", line 321, in reload_user
    user = self.user_callback(user_id)
  File "D:\blog\app\views.py", line 80, in load_user
    return User.query.get(int(id))
  File "C:\Python27\lib\site-packages\sqlalchemy\orm\query.py", line 871, in get
    ident, loading.load_on_ident)
  File "C:\Python27\lib\site-packages\sqlalchemy\orm\query.py", line 905, in _get_impl
    return fallback_fn(self, key)
  File "C:\Python27\lib\site-packages\sqlalchemy\orm\loading.py", line 231, in load_on_ident
    return q.one()
  File "C:\Python27\lib\site-packages\sqlalchemy\orm\query.py", line 2837, in one
    ret = self.one_or_none()
  File "C:\Python27\lib\site-packages\sqlalchemy\orm\query.py", line 2807, in one_or_none
    ret = list(self)
  File "C:\Python27\lib\site-packages\sqlalchemy\orm\query.py", line 2878, in __iter__
    return self._execute_and_instances(context)
  File "C:\Python27\lib\site-packages\sqlalchemy\orm\query.py", line 2901, in _execute_and_instances
    result = conn.execute(querycontext.statement, self._params)
  File "C:\Python27\lib\site-packages\sqlalchemy\engine\base.py", line 948, in execute
    return meth(self, multiparams, params)
  File "C:\Python27\lib\site-packages\sqlalchemy\sql\elements.py", line 269, in _execute_on_connection
    return connection._execute_clauseelement(self, multiparams, params)
  File "C:\Python27\lib\site-packages\sqlalchemy\engine\base.py", line 1060, in _execute_clauseelement
    compiled_sql, distilled_params
  File "C:\Python27\lib\site-packages\sqlalchemy\engine\base.py", line 1200, in _execute_context
    context)
  File "C:\Python27\lib\site-packages\sqlalchemy\engine\base.py", line 1413, in _handle_dbapi_exception
    exc_info
  File "C:\Python27\lib\site-packages\sqlalchemy\util\compat.py", line 203, in raise_from_cause
    reraise(type(exception), exception, tb=exc_tb, cause=cause)
  File "C:\Python27\lib\site-packages\sqlalchemy\engine\base.py", line 1193, in _execute_context
    context)
  File "C:\Python27\lib\site-packages\sqlalchemy\engine\default.py", line 507, in do_execute
    cursor.execute(statement, parameters)
OperationalError: (sqlite3.OperationalError) no such table: user [SQL: u'SELECT user.id AS user_id, user.nickname AS user_nickname, user.email AS user_email, user.about_me AS user_about_me, user.last_seen AS user_last_seen \nFROM user \nWHERE user.id = ?'] [parameters: (1,)] (Background on this error at: http://sqlalche.me/e/e3q8)
2018-04-16 10:13:09,229 ERROR: Exception on /login [GET] [in C:\Python27\lib\site-packages\flask\app.py:1560]
Traceback (most recent call last):
  File "C:\Python27\lib\site-packages\flask\app.py", line 1982, in wsgi_app
    response = self.full_dispatch_request()
  File "C:\Python27\lib\site-packages\flask\app.py", line 1614, in full_dispatch_request
    rv = self.handle_user_exception(e)
  File "C:\Python27\lib\site-packages\flask\app.py", line 1517, in handle_user_exception
    reraise(exc_type, exc_value, tb)
  File "C:\Python27\lib\site-packages\flask\app.py", line 1610, in full_dispatch_request
    rv = self.preprocess_request()
  File "C:\Python27\lib\site-packages\flask\app.py", line 1831, in preprocess_request
    rv = func()
  File "D:\blog\app\views.py", line 86, in before_request
    if g.user.is_authenticated:
  File "C:\Python27\lib\site-packages\werkzeug\local.py", line 347, in __getattr__
    return getattr(self._get_current_object(), name)
  File "C:\Python27\lib\site-packages\werkzeug\local.py", line 306, in _get_current_object
    return self.__local()
  File "C:\Python27\lib\site-packages\flask_login\utils.py", line 26, in <lambda>
    current_user = LocalProxy(lambda: _get_user())
  File "C:\Python27\lib\site-packages\flask_login\utils.py", line 335, in _get_user
    current_app.login_manager._load_user()
  File "C:\Python27\lib\site-packages\flask_login\login_manager.py", line 359, in _load_user
    return self.reload_user()
  File "C:\Python27\lib\site-packages\flask_login\login_manager.py", line 321, in reload_user
    user = self.user_callback(user_id)
  File "D:\blog\app\views.py", line 80, in load_user
    return User.query.get(int(id))
  File "C:\Python27\lib\site-packages\sqlalchemy\orm\query.py", line 871, in get
    ident, loading.load_on_ident)
  File "C:\Python27\lib\site-packages\sqlalchemy\orm\query.py", line 905, in _get_impl
    return fallback_fn(self, key)
  File "C:\Python27\lib\site-packages\sqlalchemy\orm\loading.py", line 231, in load_on_ident
    return q.one()
  File "C:\Python27\lib\site-packages\sqlalchemy\orm\query.py", line 2837, in one
    ret = self.one_or_none()
  File "C:\Python27\lib\site-packages\sqlalchemy\orm\query.py", line 2807, in one_or_none
    ret = list(self)
  File "C:\Python27\lib\site-packages\sqlalchemy\orm\query.py", line 2878, in __iter__
    return self._execute_and_instances(context)
  File "C:\Python27\lib\site-packages\sqlalchemy\orm\query.py", line 2901, in _execute_and_instances
    result = conn.execute(querycontext.statement, self._params)
  File "C:\Python27\lib\site-packages\sqlalchemy\engine\base.py", line 948, in execute
    return meth(self, multiparams, params)
  File "C:\Python27\lib\site-packages\sqlalchemy\sql\elements.py", line 269, in _execute_on_connection
    return connection._execute_clauseelement(self, multiparams, params)
  File "C:\Python27\lib\site-packages\sqlalchemy\engine\base.py", line 1060, in _execute_clauseelement
    compiled_sql, distilled_params
  File "C:\Python27\lib\site-packages\sqlalchemy\engine\base.py", line 1200, in _execute_context
    context)
  File "C:\Python27\lib\site-packages\sqlalchemy\engine\base.py", line 1413, in _handle_dbapi_exception
    exc_info
  File "C:\Python27\lib\site-packages\sqlalchemy\util\compat.py", line 203, in raise_from_cause
    reraise(type(exception), exception, tb=exc_tb, cause=cause)
  File "C:\Python27\lib\site-packages\sqlalchemy\engine\base.py", line 1193, in _execute_context
    context)
  File "C:\Python27\lib\site-packages\sqlalchemy\engine\default.py", line 507, in do_execute
    cursor.execute(statement, parameters)
OperationalError: (sqlite3.OperationalError) no such table: user [SQL: u'SELECT user.id AS user_id, user.nickname AS user_nickname, user.email AS user_email, user.about_me AS user_about_me, user.last_seen AS user_last_seen \nFROM user \nWHERE user.id = ?'] [parameters: (1,)] (Background on this error at: http://sqlalche.me/e/e3q8)
2018-04-16 12:52:49,605 INFO: microblog startup [in D:\blog\app\__init__.py:44]
2018-04-16 14:32:17,621 INFO: microblog startup [in D:\blog\app\__init__.py:44]
2018-04-16 14:40:23,388 INFO: microblog startup [in D:\blog\app\__init__.py:44]
2018-04-16 15:11:30,954 INFO: microblog startup [in D:\blog\app\__init__.py:44]
2018-04-16 15:57:27,812 INFO: microblog startup [in D:\blog\app\__init__.py:44]
2018-04-16 16:07:47,819 INFO: microblog startup [in D:\blog\app\__init__.py:44]
2018-04-16 16:07:54,459 INFO: microblog startup [in D:\blog\app\__init__.py:44]
2018-04-16 16:09:19,253 INFO: microblog startup [in D:\blog\app\__init__.py:44]
2018-04-16 16:09:40,582 ERROR: Exception on /index [GET] [in C:\Python27\lib\site-packages\flask\app.py:1560]
Traceback (most recent call last):
  File "C:\Python27\lib\site-packages\flask\app.py", line 1982, in wsgi_app
    response = self.full_dispatch_request()
  File "C:\Python27\lib\site-packages\flask\app.py", line 1614, in full_dispatch_request
    rv = self.handle_user_exception(e)
  File "C:\Python27\lib\site-packages\flask\app.py", line 1517, in handle_user_exception
    reraise(exc_type, exc_value, tb)
  File "C:\Python27\lib\site-packages\flask\app.py", line 1610, in full_dispatch_request
    rv = self.preprocess_request()
  File "C:\Python27\lib\site-packages\flask\app.py", line 1831, in preprocess_request
    rv = func()
  File "D:\blog\app\views.py", line 87, in before_request
    if g.user.is_authenticated():
TypeError: 'bool' object is not callable
2018-04-16 16:10:04,048 ERROR: Exception on /login [GET] [in C:\Python27\lib\site-packages\flask\app.py:1560]
Traceback (most recent call last):
  File "C:\Python27\lib\site-packages\flask\app.py", line 1982, in wsgi_app
    response = self.full_dispatch_request()
  File "C:\Python27\lib\site-packages\flask\app.py", line 1614, in full_dispatch_request
    rv = self.handle_user_exception(e)
  File "C:\Python27\lib\site-packages\flask\app.py", line 1517, in handle_user_exception
    reraise(exc_type, exc_value, tb)
  File "C:\Python27\lib\site-packages\flask\app.py", line 1610, in full_dispatch_request
    rv = self.preprocess_request()
  File "C:\Python27\lib\site-packages\flask\app.py", line 1831, in preprocess_request
    rv = func()
  File "D:\blog\app\views.py", line 87, in before_request
    if g.user.is_authenticated():
TypeError: 'bool' object is not callable
2018-04-16 16:10:06,128 ERROR: Exception on /login [GET] [in C:\Python27\lib\site-packages\flask\app.py:1560]
Traceback (most recent call last):
  File "C:\Python27\lib\site-packages\flask\app.py", line 1982, in wsgi_app
    response = self.full_dispatch_request()
  File "C:\Python27\lib\site-packages\flask\app.py", line 1614, in full_dispatch_request
    rv = self.handle_user_exception(e)
  File "C:\Python27\lib\site-packages\flask\app.py", line 1517, in handle_user_exception
    reraise(exc_type, exc_value, tb)
  File "C:\Python27\lib\site-packages\flask\app.py", line 1610, in full_dispatch_request
    rv = self.preprocess_request()
  File "C:\Python27\lib\site-packages\flask\app.py", line 1831, in preprocess_request
    rv = func()
  File "D:\blog\app\views.py", line 87, in before_request
    if g.user.is_authenticated():
TypeError: 'bool' object is not callable
2018-04-16 16:10:13,900 ERROR: Exception on /login [GET] [in C:\Python27\lib\site-packages\flask\app.py:1560]
Traceback (most recent call last):
  File "C:\Python27\lib\site-packages\flask\app.py", line 1982, in wsgi_app
    response = self.full_dispatch_request()
  File "C:\Python27\lib\site-packages\flask\app.py", line 1614, in full_dispatch_request
    rv = self.handle_user_exception(e)
  File "C:\Python27\lib\site-packages\flask\app.py", line 1517, in handle_user_exception
    reraise(exc_type, exc_value, tb)
  File "C:\Python27\lib\site-packages\flask\app.py", line 1610, in full_dispatch_request
    rv = self.preprocess_request()
  File "C:\Python27\lib\site-packages\flask\app.py", line 1831, in preprocess_request
    rv = func()
  File "D:\blog\app\views.py", line 87, in before_request
    if g.user.is_authenticated():
TypeError: 'bool' object is not callable
2018-04-16 16:10:15,926 ERROR: Exception on /login [GET] [in C:\Python27\lib\site-packages\flask\app.py:1560]
Traceback (most recent call last):
  File "C:\Python27\lib\site-packages\flask\app.py", line 1982, in wsgi_app
    response = self.full_dispatch_request()
  File "C:\Python27\lib\site-packages\flask\app.py", line 1614, in full_dispatch_request
    rv = self.handle_user_exception(e)
  File "C:\Python27\lib\site-packages\flask\app.py", line 1517, in handle_user_exception
    reraise(exc_type, exc_value, tb)
  File "C:\Python27\lib\site-packages\flask\app.py", line 1610, in full_dispatch_request
    rv = self.preprocess_request()
  File "C:\Python27\lib\site-packages\flask\app.py", line 1831, in preprocess_request
    rv = func()
  File "D:\blog\app\views.py", line 87, in before_request
    if g.user.is_authenticated():
TypeError: 'bool' object is not callable
2018-04-16 16:10:41,829 INFO: microblog startup [in D:\blog\app\__init__.py:44]
2018-04-16 16:10:48,582 ERROR: Exception on / [GET] [in C:\Python27\lib\site-packages\flask\app.py:1560]
Traceback (most recent call last):
  File "C:\Python27\lib\site-packages\flask\app.py", line 1982, in wsgi_app
    response = self.full_dispatch_request()
  File "C:\Python27\lib\site-packages\flask\app.py", line 1614, in full_dispatch_request
    rv = self.handle_user_exception(e)
  File "C:\Python27\lib\site-packages\flask\app.py", line 1517, in handle_user_exception
    reraise(exc_type, exc_value, tb)
  File "C:\Python27\lib\site-packages\flask\app.py", line 1610, in full_dispatch_request
    rv = self.preprocess_request()
  File "C:\Python27\lib\site-packages\flask\app.py", line 1831, in preprocess_request
    rv = func()
  File "D:\blog\app\views.py", line 87, in before_request
    if g.user.is_authenticated():
TypeError: 'bool' object is not callable
2018-04-16 16:10:50,634 ERROR: Exception on /login [GET] [in C:\Python27\lib\site-packages\flask\app.py:1560]
Traceback (most recent call last):
  File "C:\Python27\lib\site-packages\flask\app.py", line 1982, in wsgi_app
    response = self.full_dispatch_request()
  File "C:\Python27\lib\site-packages\flask\app.py", line 1614, in full_dispatch_request
    rv = self.handle_user_exception(e)
  File "C:\Python27\lib\site-packages\flask\app.py", line 1517, in handle_user_exception
    reraise(exc_type, exc_value, tb)
  File "C:\Python27\lib\site-packages\flask\app.py", line 1610, in full_dispatch_request
    rv = self.preprocess_request()
  File "C:\Python27\lib\site-packages\flask\app.py", line 1831, in preprocess_request
    rv = func()
  File "D:\blog\app\views.py", line 87, in before_request
    if g.user.is_authenticated():
TypeError: 'bool' object is not callable
2018-04-16 16:10:52,667 ERROR: Exception on / [GET] [in C:\Python27\lib\site-packages\flask\app.py:1560]
Traceback (most recent call last):
  File "C:\Python27\lib\site-packages\flask\app.py", line 1982, in wsgi_app
    response = self.full_dispatch_request()
  File "C:\Python27\lib\site-packages\flask\app.py", line 1614, in full_dispatch_request
    rv = self.handle_user_exception(e)
  File "C:\Python27\lib\site-packages\flask\app.py", line 1517, in handle_user_exception
    reraise(exc_type, exc_value, tb)
  File "C:\Python27\lib\site-packages\flask\app.py", line 1610, in full_dispatch_request
    rv = self.preprocess_request()
  File "C:\Python27\lib\site-packages\flask\app.py", line 1831, in preprocess_request
    rv = func()
  File "D:\blog\app\views.py", line 87, in before_request
    if g.user.is_authenticated():
TypeError: 'bool' object is not callable
2018-04-16 16:11:09,897 ERROR: Exception on / [GET] [in C:\Python27\lib\site-packages\flask\app.py:1560]
Traceback (most recent call last):
  File "C:\Python27\lib\site-packages\flask\app.py", line 1982, in wsgi_app
    response = self.full_dispatch_request()
  File "C:\Python27\lib\site-packages\flask\app.py", line 1614, in full_dispatch_request
    rv = self.handle_user_exception(e)
  File "C:\Python27\lib\site-packages\flask\app.py", line 1517, in handle_user_exception
    reraise(exc_type, exc_value, tb)
  File "C:\Python27\lib\site-packages\flask\app.py", line 1610, in full_dispatch_request
    rv = self.preprocess_request()
  File "C:\Python27\lib\site-packages\flask\app.py", line 1831, in preprocess_request
    rv = func()
  File "D:\blog\app\views.py", line 87, in before_request
    if g.user.is_authenticated():
TypeError: 'bool' object is not callable
2018-04-16 16:11:17,721 ERROR: Exception on /login [GET] [in C:\Python27\lib\site-packages\flask\app.py:1560]
Traceback (most recent call last):
  File "C:\Python27\lib\site-packages\flask\app.py", line 1982, in wsgi_app
    response = self.full_dispatch_request()
  File "C:\Python27\lib\site-packages\flask\app.py", line 1614, in full_dispatch_request
    rv = self.handle_user_exception(e)
  File "C:\Python27\lib\site-packages\flask\app.py", line 1517, in handle_user_exception
    reraise(exc_type, exc_value, tb)
  File "C:\Python27\lib\site-packages\flask\app.py", line 1610, in full_dispatch_request
    rv = self.preprocess_request()
  File "C:\Python27\lib\site-packages\flask\app.py", line 1831, in preprocess_request
    rv = func()
  File "D:\blog\app\views.py", line 87, in before_request
    if g.user.is_authenticated():
TypeError: 'bool' object is not callable
2018-04-16 16:14:17,770 INFO: microblog startup [in D:\blog\app\__init__.py:44]
2018-04-16 16:14:25,013 ERROR: Exception on /login [GET] [in C:\Python27\lib\site-packages\flask\app.py:1560]
Traceback (most recent call last):
  File "C:\Python27\lib\site-packages\flask\app.py", line 1982, in wsgi_app
    response = self.full_dispatch_request()
  File "C:\Python27\lib\site-packages\flask\app.py", line 1614, in full_dispatch_request
    rv = self.handle_user_exception(e)
  File "C:\Python27\lib\site-packages\flask\app.py", line 1517, in handle_user_exception
    reraise(exc_type, exc_value, tb)
  File "C:\Python27\lib\site-packages\flask\app.py", line 1612, in full_dispatch_request
    rv = self.dispatch_request()
  File "C:\Python27\lib\site-packages\flask\app.py", line 1598, in dispatch_request
    return self.view_functions[rule.endpoint](**req.view_args)
  File "D:\blog\app\views.py", line 128, in login
    form=form)
  File "C:\Python27\lib\site-packages\flask\templating.py", line 134, in render_template
    context, ctx.app)
  File "C:\Python27\lib\site-packages\flask\templating.py", line 116, in _render
    rv = template.render(context)
  File "C:\Python27\lib\site-packages\jinja2\environment.py", line 1008, in render
    return self.environment.handle_exception(exc_info, True)
  File "C:\Python27\lib\site-packages\jinja2\environment.py", line 780, in handle_exception
    reraise(exc_type, exc_value, tb)
  File "D:\blog\app\templates\login.html", line 2, in top-level template code
    {% extends "base.html" %}
  File "D:\blog\app\templates\base.html", line 12, in top-level template code
    {% if g.user.is_authenticated() %}
TypeError: 'bool' object is not callable
2018-04-16 16:19:39,684 INFO: microblog startup [in D:\blog\app\__init__.py:44]
2018-04-16 16:19:49,624 ERROR: Exception on /login [GET] [in C:\Python27\lib\site-packages\flask\app.py:1560]
Traceback (most recent call last):
  File "C:\Python27\lib\site-packages\flask\app.py", line 1982, in wsgi_app
    response = self.full_dispatch_request()
  File "C:\Python27\lib\site-packages\flask\app.py", line 1614, in full_dispatch_request
    rv = self.handle_user_exception(e)
  File "C:\Python27\lib\site-packages\flask\app.py", line 1517, in handle_user_exception
    reraise(exc_type, exc_value, tb)
  File "C:\Python27\lib\site-packages\flask\app.py", line 1612, in full_dispatch_request
    rv = self.dispatch_request()
  File "C:\Python27\lib\site-packages\flask\app.py", line 1598, in dispatch_request
    return self.view_functions[rule.endpoint](**req.view_args)
  File "D:\blog\app\views.py", line 127, in login
    form=form)
  File "C:\Python27\lib\site-packages\flask\templating.py", line 134, in render_template
    context, ctx.app)
  File "C:\Python27\lib\site-packages\flask\templating.py", line 116, in _render
    rv = template.render(context)
  File "C:\Python27\lib\site-packages\jinja2\environment.py", line 1008, in render
    return self.environment.handle_exception(exc_info, True)
  File "C:\Python27\lib\site-packages\jinja2\environment.py", line 780, in handle_exception
    reraise(exc_type, exc_value, tb)
  File "D:\blog\app\templates\login.html", line 2, in top-level template code
    {% extends "base.html" %}
  File "D:\blog\app\templates\base.html", line 12, in top-level template code
    {% if g.user.is_authenticated() %}
TypeError: 'bool' object is not callable
2018-04-16 16:21:26,062 INFO: microblog startup [in D:\blog\app\__init__.py:44]
2018-04-16 16:22:52,079 INFO: microblog startup [in D:\blog\app\__init__.py:44]
2018-04-16 16:35:29,141 INFO: microblog startup [in D:\blog\app\__init__.py:44]
2018-04-16 16:48:36,253 INFO: microblog startup [in D:\blog\app\__init__.py:44]
2018-04-16 16:49:45,384 ERROR: Exception on /search_results/234 [GET] [in C:\Python27\lib\site-packages\flask\app.py:1560]
Traceback (most recent call last):
  File "C:\Python27\lib\site-packages\flask\app.py", line 1982, in wsgi_app
    response = self.full_dispatch_request()
  File "C:\Python27\lib\site-packages\flask\app.py", line 1614, in full_dispatch_request
    rv = self.handle_user_exception(e)
  File "C:\Python27\lib\site-packages\flask\app.py", line 1517, in handle_user_exception
    reraise(exc_type, exc_value, tb)
  File "C:\Python27\lib\site-packages\flask\app.py", line 1612, in full_dispatch_request
    rv = self.dispatch_request()
  File "C:\Python27\lib\site-packages\flask\app.py", line 1598, in dispatch_request
    return self.view_functions[rule.endpoint](**req.view_args)
  File "C:\Python27\lib\site-packages\flask_login\utils.py", line 261, in decorated_view
    return func(*args, **kwargs)
  File "D:\blog\app\views.py", line 241, in search_results
    results = results)
  File "C:\Python27\lib\site-packages\flask\templating.py", line 134, in render_template
    context, ctx.app)
  File "C:\Python27\lib\site-packages\flask\templating.py", line 116, in _render
    rv = template.render(context)
  File "C:\Python27\lib\site-packages\jinja2\environment.py", line 1008, in render
    return self.environment.handle_exception(exc_info, True)
  File "C:\Python27\lib\site-packages\jinja2\environment.py", line 780, in handle_exception
    reraise(exc_type, exc_value, tb)
  File "D:\blog\app\templates\search_results.html", line 2, in top-level template code
    {% extends "base.html" %}
  File "D:\blog\app\templates\base.html", line 28, in top-level template code
    {% block content %}
  File "D:\blog\app\templates\search_results.html", line 7, in block "content"
    {% include 'post.html' %}
  File "D:\blog\app\templates\post.html", line 3, in top-level template code
    <td><img src={{user.avatar('50')}}></td>
  File "C:\Python27\lib\site-packages\jinja2\environment.py", line 430, in getattr
    return getattr(obj, attribute)
UndefinedError: 'user' is undefined
2018-04-16 16:49:50,993 ERROR: Exception on /search_results/234 [GET] [in C:\Python27\lib\site-packages\flask\app.py:1560]
Traceback (most recent call last):
  File "C:\Python27\lib\site-packages\flask\app.py", line 1982, in wsgi_app
    response = self.full_dispatch_request()
  File "C:\Python27\lib\site-packages\flask\app.py", line 1614, in full_dispatch_request
    rv = self.handle_user_exception(e)
  File "C:\Python27\lib\site-packages\flask\app.py", line 1517, in handle_user_exception
    reraise(exc_type, exc_value, tb)
  File "C:\Python27\lib\site-packages\flask\app.py", line 1612, in full_dispatch_request
    rv = self.dispatch_request()
  File "C:\Python27\lib\site-packages\flask\app.py", line 1598, in dispatch_request
    return self.view_functions[rule.endpoint](**req.view_args)
  File "C:\Python27\lib\site-packages\flask_login\utils.py", line 261, in decorated_view
    return func(*args, **kwargs)
  File "D:\blog\app\views.py", line 241, in search_results
    results = results)
  File "C:\Python27\lib\site-packages\flask\templating.py", line 134, in render_template
    context, ctx.app)
  File "C:\Python27\lib\site-packages\flask\templating.py", line 116, in _render
    rv = template.render(context)
  File "C:\Python27\lib\site-packages\jinja2\environment.py", line 1008, in render
    return self.environment.handle_exception(exc_info, True)
  File "C:\Python27\lib\site-packages\jinja2\environment.py", line 780, in handle_exception
    reraise(exc_type, exc_value, tb)
  File "D:\blog\app\templates\search_results.html", line 2, in top-level template code
    {% extends "base.html" %}
  File "D:\blog\app\templates\base.html", line 28, in top-level template code
    {% block content %}
  File "D:\blog\app\templates\search_results.html", line 7, in block "content"
    {% include 'post.html' %}
  File "D:\blog\app\templates\post.html", line 3, in top-level template code
    <td><img src={{user.avatar('50')}}></td>
  File "C:\Python27\lib\site-packages\jinja2\environment.py", line 430, in getattr
    return getattr(obj, attribute)
UndefinedError: 'user' is undefined
2018-04-16 16:50:11,253 ERROR: Exception on /search_results/234 [GET] [in C:\Python27\lib\site-packages\flask\app.py:1560]
Traceback (most recent call last):
  File "C:\Python27\lib\site-packages\flask\app.py", line 1982, in wsgi_app
    response = self.full_dispatch_request()
  File "C:\Python27\lib\site-packages\flask\app.py", line 1614, in full_dispatch_request
    rv = self.handle_user_exception(e)
  File "C:\Python27\lib\site-packages\flask\app.py", line 1517, in handle_user_exception
    reraise(exc_type, exc_value, tb)
  File "C:\Python27\lib\site-packages\flask\app.py", line 1612, in full_dispatch_request
    rv = self.dispatch_request()
  File "C:\Python27\lib\site-packages\flask\app.py", line 1598, in dispatch_request
    return self.view_functions[rule.endpoint](**req.view_args)
  File "C:\Python27\lib\site-packages\flask_login\utils.py", line 261, in decorated_view
    return func(*args, **kwargs)
  File "D:\blog\app\views.py", line 241, in search_results
    results = results)
  File "C:\Python27\lib\site-packages\flask\templating.py", line 134, in render_template
    context, ctx.app)
  File "C:\Python27\lib\site-packages\flask\templating.py", line 116, in _render
    rv = template.render(context)
  File "C:\Python27\lib\site-packages\jinja2\environment.py", line 1008, in render
    return self.environment.handle_exception(exc_info, True)
  File "C:\Python27\lib\site-packages\jinja2\environment.py", line 780, in handle_exception
    reraise(exc_type, exc_value, tb)
  File "D:\blog\app\templates\search_results.html", line 2, in top-level template code
    {% extends "base.html" %}
  File "D:\blog\app\templates\base.html", line 28, in top-level template code
    {% block content %}
  File "D:\blog\app\templates\search_results.html", line 7, in block "content"
    {% include 'post.html' %}
  File "D:\blog\app\templates\post.html", line 3, in top-level template code
    <td><img src={{user.avatar('50')}}></td>
  File "C:\Python27\lib\site-packages\jinja2\environment.py", line 430, in getattr
    return getattr(obj, attribute)
UndefinedError: 'user' is undefined
2018-04-16 16:50:44,608 INFO: microblog startup [in D:\blog\app\__init__.py:44]
2018-04-16 17:00:27,035 ERROR: Exception on /search_results/post [GET] [in C:\Python27\lib\site-packages\flask\app.py:1560]
Traceback (most recent call last):
  File "C:\Python27\lib\site-packages\flask\app.py", line 1982, in wsgi_app
    response = self.full_dispatch_request()
  File "C:\Python27\lib\site-packages\flask\app.py", line 1614, in full_dispatch_request
    rv = self.handle_user_exception(e)
  File "C:\Python27\lib\site-packages\flask\app.py", line 1517, in handle_user_exception
    reraise(exc_type, exc_value, tb)
  File "C:\Python27\lib\site-packages\flask\app.py", line 1612, in full_dispatch_request
    rv = self.dispatch_request()
  File "C:\Python27\lib\site-packages\flask\app.py", line 1598, in dispatch_request
    return self.view_functions[rule.endpoint](**req.view_args)
  File "C:\Python27\lib\site-packages\flask_login\utils.py", line 261, in decorated_view
    return func(*args, **kwargs)
  File "D:\blog\app\views.py", line 241, in search_results
    results = results)
  File "C:\Python27\lib\site-packages\flask\templating.py", line 134, in render_template
    context, ctx.app)
  File "C:\Python27\lib\site-packages\flask\templating.py", line 116, in _render
    rv = template.render(context)
  File "C:\Python27\lib\site-packages\jinja2\environment.py", line 1008, in render
    return self.environment.handle_exception(exc_info, True)
  File "C:\Python27\lib\site-packages\jinja2\environment.py", line 780, in handle_exception
    reraise(exc_type, exc_value, tb)
  File "D:\blog\app\templates\search_results.html", line 2, in top-level template code
    {% extends "base.html" %}
  File "D:\blog\app\templates\base.html", line 28, in top-level template code
    {% block content %}
  File "D:\blog\app\templates\search_results.html", line 7, in block "content"
    {% include 'post.html' %}
  File "D:\blog\app\templates\post.html", line 3, in top-level template code
    <td><img src={{user.avatar('50')}}></td>
  File "C:\Python27\lib\site-packages\jinja2\environment.py", line 430, in getattr
    return getattr(obj, attribute)
UndefinedError: 'user' is undefined
2018-04-16 17:00:29,111 ERROR: Exception on /search_results/post [GET] [in C:\Python27\lib\site-packages\flask\app.py:1560]
Traceback (most recent call last):
  File "C:\Python27\lib\site-packages\flask\app.py", line 1982, in wsgi_app
    response = self.full_dispatch_request()
  File "C:\Python27\lib\site-packages\flask\app.py", line 1614, in full_dispatch_request
    rv = self.handle_user_exception(e)
  File "C:\Python27\lib\site-packages\flask\app.py", line 1517, in handle_user_exception
    reraise(exc_type, exc_value, tb)
  File "C:\Python27\lib\site-packages\flask\app.py", line 1612, in full_dispatch_request
    rv = self.dispatch_request()
  File "C:\Python27\lib\site-packages\flask\app.py", line 1598, in dispatch_request
    return self.view_functions[rule.endpoint](**req.view_args)
  File "C:\Python27\lib\site-packages\flask_login\utils.py", line 261, in decorated_view
    return func(*args, **kwargs)
  File "D:\blog\app\views.py", line 241, in search_results
    results = results)
  File "C:\Python27\lib\site-packages\flask\templating.py", line 134, in render_template
    context, ctx.app)
  File "C:\Python27\lib\site-packages\flask\templating.py", line 116, in _render
    rv = template.render(context)
  File "C:\Python27\lib\site-packages\jinja2\environment.py", line 1008, in render
    return self.environment.handle_exception(exc_info, True)
  File "C:\Python27\lib\site-packages\jinja2\environment.py", line 780, in handle_exception
    reraise(exc_type, exc_value, tb)
  File "D:\blog\app\templates\search_results.html", line 2, in top-level template code
    {% extends "base.html" %}
  File "D:\blog\app\templates\base.html", line 28, in top-level template code
    {% block content %}
  File "D:\blog\app\templates\search_results.html", line 7, in block "content"
    {% include 'post.html' %}
  File "D:\blog\app\templates\post.html", line 3, in top-level template code
    <td><img src={{user.avatar('50')}}></td>
  File "C:\Python27\lib\site-packages\jinja2\environment.py", line 430, in getattr
    return getattr(obj, attribute)
UndefinedError: 'user' is undefined
2018-04-16 17:00:33,964 ERROR: Exception on /search_results/post [GET] [in C:\Python27\lib\site-packages\flask\app.py:1560]
Traceback (most recent call last):
  File "C:\Python27\lib\site-packages\flask\app.py", line 1982, in wsgi_app
    response = self.full_dispatch_request()
  File "C:\Python27\lib\site-packages\flask\app.py", line 1614, in full_dispatch_request
    rv = self.handle_user_exception(e)
  File "C:\Python27\lib\site-packages\flask\app.py", line 1517, in handle_user_exception
    reraise(exc_type, exc_value, tb)
  File "C:\Python27\lib\site-packages\flask\app.py", line 1612, in full_dispatch_request
    rv = self.dispatch_request()
  File "C:\Python27\lib\site-packages\flask\app.py", line 1598, in dispatch_request
    return self.view_functions[rule.endpoint](**req.view_args)
  File "C:\Python27\lib\site-packages\flask_login\utils.py", line 261, in decorated_view
    return func(*args, **kwargs)
  File "D:\blog\app\views.py", line 241, in search_results
    results = results)
  File "C:\Python27\lib\site-packages\flask\templating.py", line 134, in render_template
    context, ctx.app)
  File "C:\Python27\lib\site-packages\flask\templating.py", line 116, in _render
    rv = template.render(context)
  File "C:\Python27\lib\site-packages\jinja2\environment.py", line 1008, in render
    return self.environment.handle_exception(exc_info, True)
  File "C:\Python27\lib\site-packages\jinja2\environment.py", line 780, in handle_exception
    reraise(exc_type, exc_value, tb)
  File "D:\blog\app\templates\search_results.html", line 2, in top-level template code
    {% extends "base.html" %}
  File "D:\blog\app\templates\base.html", line 28, in top-level template code
    {% block content %}
  File "D:\blog\app\templates\search_results.html", line 7, in block "content"
    {% include 'post.html' %}
  File "D:\blog\app\templates\post.html", line 3, in top-level template code
    <td><img src={{user.avatar('50')}}></td>
  File "C:\Python27\lib\site-packages\jinja2\environment.py", line 430, in getattr
    return getattr(obj, attribute)
UndefinedError: 'user' is undefined
2018-04-16 17:00:39,729 ERROR: Exception on /search_results/post [GET] [in C:\Python27\lib\site-packages\flask\app.py:1560]
Traceback (most recent call last):
  File "C:\Python27\lib\site-packages\flask\app.py", line 1982, in wsgi_app
    response = self.full_dispatch_request()
  File "C:\Python27\lib\site-packages\flask\app.py", line 1614, in full_dispatch_request
    rv = self.handle_user_exception(e)
  File "C:\Python27\lib\site-packages\flask\app.py", line 1517, in handle_user_exception
    reraise(exc_type, exc_value, tb)
  File "C:\Python27\lib\site-packages\flask\app.py", line 1612, in full_dispatch_request
    rv = self.dispatch_request()
  File "C:\Python27\lib\site-packages\flask\app.py", line 1598, in dispatch_request
    return self.view_functions[rule.endpoint](**req.view_args)
  File "C:\Python27\lib\site-packages\flask_login\utils.py", line 261, in decorated_view
    return func(*args, **kwargs)
  File "D:\blog\app\views.py", line 241, in search_results
    results = results)
  File "C:\Python27\lib\site-packages\flask\templating.py", line 134, in render_template
    context, ctx.app)
  File "C:\Python27\lib\site-packages\flask\templating.py", line 116, in _render
    rv = template.render(context)
  File "C:\Python27\lib\site-packages\jinja2\environment.py", line 1008, in render
    return self.environment.handle_exception(exc_info, True)
  File "C:\Python27\lib\site-packages\jinja2\environment.py", line 780, in handle_exception
    reraise(exc_type, exc_value, tb)
  File "D:\blog\app\templates\search_results.html", line 2, in top-level template code
    {% extends "base.html" %}
  File "D:\blog\app\templates\base.html", line 28, in top-level template code
    {% block content %}
  File "D:\blog\app\templates\search_results.html", line 7, in block "content"
    {% include 'post.html' %}
  File "D:\blog\app\templates\post.html", line 3, in top-level template code
    <td><img src={{user.avatar('50')}}></td>
  File "C:\Python27\lib\site-packages\jinja2\environment.py", line 430, in getattr
    return getattr(obj, attribute)
UndefinedError: 'user' is undefined
2018-04-16 17:00:47,273 ERROR: Exception on /search_results/post [GET] [in C:\Python27\lib\site-packages\flask\app.py:1560]
Traceback (most recent call last):
  File "C:\Python27\lib\site-packages\flask\app.py", line 1982, in wsgi_app
    response = self.full_dispatch_request()
  File "C:\Python27\lib\site-packages\flask\app.py", line 1614, in full_dispatch_request
    rv = self.handle_user_exception(e)
  File "C:\Python27\lib\site-packages\flask\app.py", line 1517, in handle_user_exception
    reraise(exc_type, exc_value, tb)
  File "C:\Python27\lib\site-packages\flask\app.py", line 1612, in full_dispatch_request
    rv = self.dispatch_request()
  File "C:\Python27\lib\site-packages\flask\app.py", line 1598, in dispatch_request
    return self.view_functions[rule.endpoint](**req.view_args)
  File "C:\Python27\lib\site-packages\flask_login\utils.py", line 261, in decorated_view
    return func(*args, **kwargs)
  File "D:\blog\app\views.py", line 241, in search_results
    results = results)
  File "C:\Python27\lib\site-packages\flask\templating.py", line 134, in render_template
    context, ctx.app)
  File "C:\Python27\lib\site-packages\flask\templating.py", line 116, in _render
    rv = template.render(context)
  File "C:\Python27\lib\site-packages\jinja2\environment.py", line 1008, in render
    return self.environment.handle_exception(exc_info, True)
  File "C:\Python27\lib\site-packages\jinja2\environment.py", line 780, in handle_exception
    reraise(exc_type, exc_value, tb)
  File "D:\blog\app\templates\search_results.html", line 2, in top-level template code
    {% extends "base.html" %}
  File "D:\blog\app\templates\base.html", line 28, in top-level template code
    {% block content %}
  File "D:\blog\app\templates\search_results.html", line 7, in block "content"
    {% include 'post.html' %}
  File "D:\blog\app\templates\post.html", line 3, in top-level template code
    <td><img src={{user.avatar('50')}}></td>
  File "C:\Python27\lib\site-packages\jinja2\environment.py", line 430, in getattr
    return getattr(obj, attribute)
UndefinedError: 'user' is undefined
2018-04-16 17:00:50,966 ERROR: Exception on /search_results/post [GET] [in C:\Python27\lib\site-packages\flask\app.py:1560]
Traceback (most recent call last):
  File "C:\Python27\lib\site-packages\flask\app.py", line 1982, in wsgi_app
    response = self.full_dispatch_request()
  File "C:\Python27\lib\site-packages\flask\app.py", line 1614, in full_dispatch_request
    rv = self.handle_user_exception(e)
  File "C:\Python27\lib\site-packages\flask\app.py", line 1517, in handle_user_exception
    reraise(exc_type, exc_value, tb)
  File "C:\Python27\lib\site-packages\flask\app.py", line 1612, in full_dispatch_request
    rv = self.dispatch_request()
  File "C:\Python27\lib\site-packages\flask\app.py", line 1598, in dispatch_request
    return self.view_functions[rule.endpoint](**req.view_args)
  File "C:\Python27\lib\site-packages\flask_login\utils.py", line 261, in decorated_view
    return func(*args, **kwargs)
  File "D:\blog\app\views.py", line 241, in search_results
    results = results)
  File "C:\Python27\lib\site-packages\flask\templating.py", line 134, in render_template
    context, ctx.app)
  File "C:\Python27\lib\site-packages\flask\templating.py", line 116, in _render
    rv = template.render(context)
  File "C:\Python27\lib\site-packages\jinja2\environment.py", line 1008, in render
    return self.environment.handle_exception(exc_info, True)
  File "C:\Python27\lib\site-packages\jinja2\environment.py", line 780, in handle_exception
    reraise(exc_type, exc_value, tb)
  File "D:\blog\app\templates\search_results.html", line 2, in top-level template code
    {% extends "base.html" %}
  File "D:\blog\app\templates\base.html", line 28, in top-level template code
    {% block content %}
  File "D:\blog\app\templates\search_results.html", line 7, in block "content"
    {% include 'post.html' %}
  File "D:\blog\app\templates\post.html", line 3, in top-level template code
    <td><img src={{user.avatar('50')}}></td>
  File "C:\Python27\lib\site-packages\jinja2\environment.py", line 430, in getattr
    return getattr(obj, attribute)
UndefinedError: 'user' is undefined
2018-04-16 17:01:11,229 ERROR: Exception on /search_results/post [GET] [in C:\Python27\lib\site-packages\flask\app.py:1560]
Traceback (most recent call last):
  File "C:\Python27\lib\site-packages\flask\app.py", line 1982, in wsgi_app
    response = self.full_dispatch_request()
  File "C:\Python27\lib\site-packages\flask\app.py", line 1614, in full_dispatch_request
    rv = self.handle_user_exception(e)
  File "C:\Python27\lib\site-packages\flask\app.py", line 1517, in handle_user_exception
    reraise(exc_type, exc_value, tb)
  File "C:\Python27\lib\site-packages\flask\app.py", line 1612, in full_dispatch_request
    rv = self.dispatch_request()
  File "C:\Python27\lib\site-packages\flask\app.py", line 1598, in dispatch_request
    return self.view_functions[rule.endpoint](**req.view_args)
  File "C:\Python27\lib\site-packages\flask_login\utils.py", line 261, in decorated_view
    return func(*args, **kwargs)
  File "D:\blog\app\views.py", line 241, in search_results
    results = results)
  File "C:\Python27\lib\site-packages\flask\templating.py", line 134, in render_template
    context, ctx.app)
  File "C:\Python27\lib\site-packages\flask\templating.py", line 116, in _render
    rv = template.render(context)
  File "C:\Python27\lib\site-packages\jinja2\environment.py", line 1008, in render
    return self.environment.handle_exception(exc_info, True)
  File "C:\Python27\lib\site-packages\jinja2\environment.py", line 780, in handle_exception
    reraise(exc_type, exc_value, tb)
  File "D:\blog\app\templates\search_results.html", line 2, in top-level template code
    {% extends "base.html" %}
  File "D:\blog\app\templates\base.html", line 28, in top-level template code
    {% block content %}
  File "D:\blog\app\templates\search_results.html", line 7, in block "content"
    {% include 'post.html' %}
  File "D:\blog\app\templates\post.html", line 3, in top-level template code
    <td><img src={{user.avatar('50')}}></td>
  File "C:\Python27\lib\site-packages\jinja2\environment.py", line 430, in getattr
    return getattr(obj, attribute)
UndefinedError: 'user' is undefined
2018-04-16 17:01:33,124 INFO: microblog startup [in D:\blog\app\__init__.py:44]
2018-04-16 17:16:20,355 INFO: microblog startup [in D:\blog\app\__init__.py:44]
2018-04-16 17:16:29,933 ERROR: Exception on /search_results/234 [GET] [in C:\Python27\lib\site-packages\flask\app.py:1560]
Traceback (most recent call last):
  File "C:\Python27\lib\site-packages\flask\app.py", line 1982, in wsgi_app
    response = self.full_dispatch_request()
  File "C:\Python27\lib\site-packages\flask\app.py", line 1614, in full_dispatch_request
    rv = self.handle_user_exception(e)
  File "C:\Python27\lib\site-packages\flask\app.py", line 1517, in handle_user_exception
    reraise(exc_type, exc_value, tb)
  File "C:\Python27\lib\site-packages\flask\app.py", line 1612, in full_dispatch_request
    rv = self.dispatch_request()
  File "C:\Python27\lib\site-packages\flask\app.py", line 1598, in dispatch_request
    return self.view_functions[rule.endpoint](**req.view_args)
  File "C:\Python27\lib\site-packages\flask_login\utils.py", line 261, in decorated_view
    return func(*args, **kwargs)
  File "D:\blog\app\views.py", line 238, in search_results
    results = Post.query.whoosh_search(query, MAX_SEARCH_RESULTS).all()
AttributeError: 'BaseQuery' object has no attribute 'whoosh_search'
2018-04-16 17:20:32,673 INFO: microblog startup [in D:\blog\app\__init__.py:44]
2018-04-16 17:20:43,099 ERROR: Exception on /search_results/post [GET] [in C:\Python27\lib\site-packages\flask\app.py:1560]
Traceback (most recent call last):
  File "C:\Python27\lib\site-packages\flask\app.py", line 1982, in wsgi_app
    response = self.full_dispatch_request()
  File "C:\Python27\lib\site-packages\flask\app.py", line 1614, in full_dispatch_request
    rv = self.handle_user_exception(e)
  File "C:\Python27\lib\site-packages\flask\app.py", line 1517, in handle_user_exception
    reraise(exc_type, exc_value, tb)
  File "C:\Python27\lib\site-packages\flask\app.py", line 1612, in full_dispatch_request
    rv = self.dispatch_request()
  File "C:\Python27\lib\site-packages\flask\app.py", line 1598, in dispatch_request
    return self.view_functions[rule.endpoint](**req.view_args)
  File "C:\Python27\lib\site-packages\flask_login\utils.py", line 261, in decorated_view
    return func(*args, **kwargs)
  File "D:\blog\app\views.py", line 238, in search_results
    results = Post.query.whoosh_search(query, MAX_SEARCH_RESULTS).all()
AttributeError: 'BaseQuery' object has no attribute 'whoosh_search'
2018-04-16 17:24:16,780 INFO: microblog startup [in D:\blog\app\__init__.py:44]
2018-04-16 17:24:26,075 ERROR: Exception on /search_results/234 [GET] [in C:\Python27\lib\site-packages\flask\app.py:1560]
Traceback (most recent call last):
  File "C:\Python27\lib\site-packages\flask\app.py", line 1982, in wsgi_app
    response = self.full_dispatch_request()
  File "C:\Python27\lib\site-packages\flask\app.py", line 1614, in full_dispatch_request
    rv = self.handle_user_exception(e)
  File "C:\Python27\lib\site-packages\flask\app.py", line 1517, in handle_user_exception
    reraise(exc_type, exc_value, tb)
  File "C:\Python27\lib\site-packages\flask\app.py", line 1612, in full_dispatch_request
    rv = self.dispatch_request()
  File "C:\Python27\lib\site-packages\flask\app.py", line 1598, in dispatch_request
    return self.view_functions[rule.endpoint](**req.view_args)
  File "C:\Python27\lib\site-packages\flask_login\utils.py", line 261, in decorated_view
    return func(*args, **kwargs)
  File "D:\blog\app\views.py", line 238, in search_results
    results = Post.query.whoosh_search(query, MAX_SEARCH_RESULTS).all()
AttributeError: 'BaseQuery' object has no attribute 'whoosh_search'
2018-04-16 17:24:53,131 INFO: microblog startup [in D:\blog\app\__init__.py:44]
2018-04-16 17:26:17,380 INFO: microblog startup [in D:\blog\app\__init__.py:44]
2018-04-18 11:53:51,767 INFO: microblog startup [in D:\blog\app\__init__.py:47]
2018-04-18 15:07:00,466 INFO: microblog startup [in D:\blog\app\__init__.py:47]
2018-04-18 15:09:28,687 INFO: microblog startup [in D:\blog\app\__init__.py:47]
2018-04-18 15:18:39,634 INFO: microblog startup [in D:\blog\app\__init__.py:47]
2018-04-18 15:58:31,239 INFO: microblog startup [in D:\blog\app\__init__.py:47]
2018-04-18 15:58:39,977 INFO: microblog startup [in D:\blog\app\__init__.py:47]
2018-04-18 16:23:38,319 INFO: microblog startup [in D:\blog\app\__init__.py:47]
2018-04-18 17:01:25,993 INFO: microblog startup [in D:\blog\app\__init__.py:46]
2018-04-19 13:54:28,845 INFO: microblog startup [in D:\blog\app\__init__.py:48]
2018-04-19 16:18:25,881 INFO: microblog startup [in D:\blog\app\__init__.py:48]
2018-04-20 09:33:13,056 INFO: microblog startup [in D:\blog\app\__init__.py:54]
2018-04-20 09:51:06,252 INFO: microblog startup [in D:\blog\app\__init__.py:54]
2018-04-20 09:51:08,655 ERROR: Exception on / [GET] [in C:\Python27\lib\site-packages\flask\app.py:1560]
Traceback (most recent call last):
  File "C:\Python27\lib\site-packages\flask\app.py", line 1982, in wsgi_app
    response = self.full_dispatch_request()
  File "C:\Python27\lib\site-packages\flask\app.py", line 1614, in full_dispatch_request
    rv = self.handle_user_exception(e)
  File "C:\Python27\lib\site-packages\flask\app.py", line 1517, in handle_user_exception
    reraise(exc_type, exc_value, tb)
  File "C:\Python27\lib\site-packages\flask\app.py", line 1610, in full_dispatch_request
    rv = self.preprocess_request()
  File "C:\Python27\lib\site-packages\flask\app.py", line 1831, in preprocess_request
    rv = func()
  File "D:\blog\app\views.py", line 93, in before_request
    if g.user.is_authenticated():
TypeError: 'bool' object is not callable
2018-04-20 09:51:14,061 ERROR: Exception on /favicon.ico [GET] [in C:\Python27\lib\site-packages\flask\app.py:1560]
Traceback (most recent call last):
  File "C:\Python27\lib\site-packages\flask\app.py", line 1982, in wsgi_app
    response = self.full_dispatch_request()
  File "C:\Python27\lib\site-packages\flask\app.py", line 1614, in full_dispatch_request
    rv = self.handle_user_exception(e)
  File "C:\Python27\lib\site-packages\flask\app.py", line 1517, in handle_user_exception
    reraise(exc_type, exc_value, tb)
  File "C:\Python27\lib\site-packages\flask\app.py", line 1610, in full_dispatch_request
    rv = self.preprocess_request()
  File "C:\Python27\lib\site-packages\flask\app.py", line 1831, in preprocess_request
    rv = func()
  File "D:\blog\app\views.py", line 93, in before_request
    if g.user.is_authenticated():
TypeError: 'bool' object is not callable
2018-04-20 09:51:19,161 ERROR: Exception on /login [GET] [in C:\Python27\lib\site-packages\flask\app.py:1560]
Traceback (most recent call last):
  File "C:\Python27\lib\site-packages\flask\app.py", line 1982, in wsgi_app
    response = self.full_dispatch_request()
  File "C:\Python27\lib\site-packages\flask\app.py", line 1614, in full_dispatch_request
    rv = self.handle_user_exception(e)
  File "C:\Python27\lib\site-packages\flask\app.py", line 1517, in handle_user_exception
    reraise(exc_type, exc_value, tb)
  File "C:\Python27\lib\site-packages\flask\app.py", line 1610, in full_dispatch_request
    rv = self.preprocess_request()
  File "C:\Python27\lib\site-packages\flask\app.py", line 1831, in preprocess_request
    rv = func()
  File "D:\blog\app\views.py", line 93, in before_request
    if g.user.is_authenticated():
TypeError: 'bool' object is not callable
2018-04-20 09:51:24,354 ERROR: Exception on /favicon.ico [GET] [in C:\Python27\lib\site-packages\flask\app.py:1560]
Traceback (most recent call last):
  File "C:\Python27\lib\site-packages\flask\app.py", line 1982, in wsgi_app
    response = self.full_dispatch_request()
  File "C:\Python27\lib\site-packages\flask\app.py", line 1614, in full_dispatch_request
    rv = self.handle_user_exception(e)
  File "C:\Python27\lib\site-packages\flask\app.py", line 1517, in handle_user_exception
    reraise(exc_type, exc_value, tb)
  File "C:\Python27\lib\site-packages\flask\app.py", line 1610, in full_dispatch_request
    rv = self.preprocess_request()
  File "C:\Python27\lib\site-packages\flask\app.py", line 1831, in preprocess_request
    rv = func()
  File "D:\blog\app\views.py", line 93, in before_request
    if g.user.is_authenticated():
TypeError: 'bool' object is not callable
2018-04-20 09:51:36,114 ERROR: Exception on /login [GET] [in C:\Python27\lib\site-packages\flask\app.py:1560]
Traceback (most recent call last):
  File "C:\Python27\lib\site-packages\flask\app.py", line 1982, in wsgi_app
    response = self.full_dispatch_request()
  File "C:\Python27\lib\site-packages\flask\app.py", line 1614, in full_dispatch_request
    rv = self.handle_user_exception(e)
  File "C:\Python27\lib\site-packages\flask\app.py", line 1517, in handle_user_exception
    reraise(exc_type, exc_value, tb)
  File "C:\Python27\lib\site-packages\flask\app.py", line 1610, in full_dispatch_request
    rv = self.preprocess_request()
  File "C:\Python27\lib\site-packages\flask\app.py", line 1831, in preprocess_request
    rv = func()
  File "D:\blog\app\views.py", line 93, in before_request
    if g.user.is_authenticated():
TypeError: 'bool' object is not callable
2018-04-20 09:51:41,237 ERROR: Exception on /favicon.ico [GET] [in C:\Python27\lib\site-packages\flask\app.py:1560]
Traceback (most recent call last):
  File "C:\Python27\lib\site-packages\flask\app.py", line 1982, in wsgi_app
    response = self.full_dispatch_request()
  File "C:\Python27\lib\site-packages\flask\app.py", line 1614, in full_dispatch_request
    rv = self.handle_user_exception(e)
  File "C:\Python27\lib\site-packages\flask\app.py", line 1517, in handle_user_exception
    reraise(exc_type, exc_value, tb)
  File "C:\Python27\lib\site-packages\flask\app.py", line 1610, in full_dispatch_request
    rv = self.preprocess_request()
  File "C:\Python27\lib\site-packages\flask\app.py", line 1831, in preprocess_request
    rv = func()
  File "D:\blog\app\views.py", line 93, in before_request
    if g.user.is_authenticated():
TypeError: 'bool' object is not callable
2018-04-20 09:52:11,687 INFO: microblog startup [in D:\blog\app\__init__.py:54]
2018-04-20 10:15:36,043 INFO: microblog startup [in D:\blog\app\__init__.py:54]
